<testsuites>
	<testsuite id="1" tests="8" failures="5" package="F:\Work\oxygen\autotests\OxyMi\specs\OxyMi\06_Get Calendars\downloading_calendars.spec" time="105.275" timestamp="2018-11-21T11:25:30" name="OxyMi Calendars downloading" errors="0" hostname="MOKYCH-A-02-PC">
		<properties></properties>
		<testcase classname="OxyMi Calendars downloading" name="Get Calendars with valid token" time="15.243"></testcase>
		<testcase classname="OxyMi Calendars downloading" name="Get big amount of Calendars" time="0.276">
			<failure message="Peek authenticated accounts with tags &#34;big data&#34;&#xA;Step Execution Failure: &#39;No matching accounts with tags [&#39;big data&#39;] found!&#39;" type="Peek authenticated accounts with tags &#34;big data&#34;&#xA;Step Execution Failure: &#39;No matching accounts with tags [&#39;big data&#39;] found!&#39;">Traceback (most recent call last):&#xA;  File &#34;C:\Users\mokych.andrey\AppData\Roaming\Python\Python37\site-packages\getgauge\executor.py&#34;, line 31, in execute_method&#xA;    func(*params)&#xA;  File &#34;F:\Work\oxygen\autotests\EnvUtils\EnvironmentBase.py&#34;, line 44, in wrapper&#xA;    raise err&#xA;  File &#34;F:\Work\oxygen\autotests\EnvUtils\EnvironmentBase.py&#34;, line 38, in wrapper&#xA;    return func(get_env(), *args, **kwargs)&#xA;  File &#34;F:\Work\oxygen\autotests\OxyMi\step_impl\step_impl.py&#34;, line 66, in peek_authenticated_accounts&#xA;    accs = env.get_authenticated_accounts_with_tags(tags_list)&#xA;  File &#34;F:\Work\oxygen\autotests\EnvUtils\mixins\CloudClient.py&#34;, line 24, in get_authenticated_accounts_with_tags&#xA;    return CloudClient.filter_accounts_by_tags(accounts, tags)&#xA;  File &#34;F:\Work\oxygen\autotests\EnvUtils\mixins\CloudClient.py&#34;, line 42, in filter_accounts_by_tags&#xA;    &#39;No matching accounts with tags {} found!&#39;.format(tags))&#xA;RuntimeError: No matching accounts with tags [&#39;big data&#39;] found!&#xA;</failure>
		</testcase>
		<testcase classname="OxyMi Calendars downloading" name="Get Calendars with invalid token" time="1.337">
			<failure message="Multiple failures" type="Multiple failures">Check that HRESULT of &#34;DownloadCalendars&#34; is &#34;E_AUTHORIZATION_ERROR&#34;&#xA;Step Execution Failure: &#39;Error code E_USR_PWD_ERROR not matches expected: &#39;E_AUTHORIZATION_ERROR&#39;&#39;&#xA;Traceback (most recent call last):&#xA;  File &#34;C:\Users\mokych.andrey\AppData\Roaming\Python\Python37\site-packages\getgauge\executor.py&#34;, line 31, in execute_method&#xA;    func(*params)&#xA;  File &#34;F:\Work\oxygen\autotests\TestUtils\threads.py&#34;, line 88, in wrapper&#xA;    return func(*args, threads=background_threads, **kwargs)&#xA;  File &#34;F:\Work\oxygen\autotests\TestUtils\common_steps.py&#34;, line 25, in check_hresult&#xA;    actual_error, &#39;, &#39;.join(expecteds)))&#xA;AssertionError: Error code E_USR_PWD_ERROR not matches expected: &#39;E_AUTHORIZATION_ERROR&#39;&#xA;&#xA;&#xA;Check that &#34;DownloadCalendars&#34; created database&#xA;Step Execution Failure: &#39;File F:\Work\oxygen\autotests\OxyMi\temp\OxyMi\06_Get Calendars\downloading_calendars\get_calendars_with_invalid_token\uuxr@erasf.com\simple path\Calendars\Calendars.db does not exist&#39;&#xA;Traceback (most recent call last):&#xA;  File &#34;C:\Users\mokych.andrey\AppData\Roaming\Python\Python37\site-packages\getgauge\executor.py&#34;, line 31, in execute_method&#xA;    func(*params)&#xA;  File &#34;F:\Work\oxygen\autotests\OxyMi\step_impl\verification_steps.py&#34;, line 45, in check_database_created&#xA;    verify_file_exists(db_path)&#xA;  File &#34;F:\Work\oxygen\autotests\TestUtils\fs.py&#34;, line 25, in verify_file_exists&#xA;    raise AssertionError(&#39;File {} does not exist&#39;.format(filepath))&#xA;AssertionError: File F:\Work\oxygen\autotests\OxyMi\temp\OxyMi\06_Get Calendars\downloading_calendars\get_calendars_with_invalid_token\uuxr@erasf.com\simple path\Calendars\Calendars.db does not exist&#xA;</failure>
		</testcase>
		<testcase classname="OxyMi Calendars downloading" name="Get empty Calendars list" time="0.234">
			<failure message="Peek authenticated accounts with tags &#34;empty data&#34;&#xA;Step Execution Failure: &#39;No matching accounts with tags [&#39;empty data&#39;] found!&#39;" type="Peek authenticated accounts with tags &#34;empty data&#34;&#xA;Step Execution Failure: &#39;No matching accounts with tags [&#39;empty data&#39;] found!&#39;">Traceback (most recent call last):&#xA;  File &#34;C:\Users\mokych.andrey\AppData\Roaming\Python\Python37\site-packages\getgauge\executor.py&#34;, line 31, in execute_method&#xA;    func(*params)&#xA;  File &#34;F:\Work\oxygen\autotests\EnvUtils\EnvironmentBase.py&#34;, line 44, in wrapper&#xA;    raise err&#xA;  File &#34;F:\Work\oxygen\autotests\EnvUtils\EnvironmentBase.py&#34;, line 38, in wrapper&#xA;    return func(get_env(), *args, **kwargs)&#xA;  File &#34;F:\Work\oxygen\autotests\OxyMi\step_impl\step_impl.py&#34;, line 66, in peek_authenticated_accounts&#xA;    accs = env.get_authenticated_accounts_with_tags(tags_list)&#xA;  File &#34;F:\Work\oxygen\autotests\EnvUtils\mixins\CloudClient.py&#34;, line 24, in get_authenticated_accounts_with_tags&#xA;    return CloudClient.filter_accounts_by_tags(accounts, tags)&#xA;  File &#34;F:\Work\oxygen\autotests\EnvUtils\mixins\CloudClient.py&#34;, line 42, in filter_accounts_by_tags&#xA;    &#39;No matching accounts with tags {} found!&#39;.format(tags))&#xA;RuntimeError: No matching accounts with tags [&#39;empty data&#39;] found!&#xA;</failure>
		</testcase>
		<testcase classname="OxyMi Calendars downloading" name="Get Calendars from account without devices" time="0.217">
			<failure message="Peek authenticated accounts with tags &#34;without devices&#34;&#xA;Step Execution Failure: &#39;No matching accounts with tags [&#39;without devices&#39;] found!&#39;" type="Peek authenticated accounts with tags &#34;without devices&#34;&#xA;Step Execution Failure: &#39;No matching accounts with tags [&#39;without devices&#39;] found!&#39;">Traceback (most recent call last):&#xA;  File &#34;C:\Users\mokych.andrey\AppData\Roaming\Python\Python37\site-packages\getgauge\executor.py&#34;, line 31, in execute_method&#xA;    func(*params)&#xA;  File &#34;F:\Work\oxygen\autotests\EnvUtils\EnvironmentBase.py&#34;, line 44, in wrapper&#xA;    raise err&#xA;  File &#34;F:\Work\oxygen\autotests\EnvUtils\EnvironmentBase.py&#34;, line 38, in wrapper&#xA;    return func(get_env(), *args, **kwargs)&#xA;  File &#34;F:\Work\oxygen\autotests\OxyMi\step_impl\step_impl.py&#34;, line 66, in peek_authenticated_accounts&#xA;    accs = env.get_authenticated_accounts_with_tags(tags_list)&#xA;  File &#34;F:\Work\oxygen\autotests\EnvUtils\mixins\CloudClient.py&#34;, line 24, in get_authenticated_accounts_with_tags&#xA;    return CloudClient.filter_accounts_by_tags(accounts, tags)&#xA;  File &#34;F:\Work\oxygen\autotests\EnvUtils\mixins\CloudClient.py&#34;, line 42, in filter_accounts_by_tags&#xA;    &#39;No matching accounts with tags {} found!&#39;.format(tags))&#xA;RuntimeError: No matching accounts with tags [&#39;without devices&#39;] found!&#xA;</failure>
		</testcase>
		<testcase classname="OxyMi Calendars downloading" name="Get Calendars with Chinese proxy" time="23.673"></testcase>
		<testcase classname="OxyMi Calendars downloading" name="Get Calendars with Russian proxy" time="40.449">
			<failure message="Multiple failures" type="Multiple failures">Check that HRESULT of &#34;DownloadCalendars&#34; is &#34;S_OK&#34;&#xA;Step Execution Failure: &#39;Error code E_NETWORK_ERROR not matches expected: &#39;S_OK&#39;&#39;&#xA;Traceback (most recent call last):&#xA;  File &#34;C:\Users\mokych.andrey\AppData\Roaming\Python\Python37\site-packages\getgauge\executor.py&#34;, line 31, in execute_method&#xA;    func(*params)&#xA;  File &#34;F:\Work\oxygen\autotests\TestUtils\threads.py&#34;, line 88, in wrapper&#xA;    return func(*args, threads=background_threads, **kwargs)&#xA;  File &#34;F:\Work\oxygen\autotests\TestUtils\common_steps.py&#34;, line 25, in check_hresult&#xA;    actual_error, &#39;, &#39;.join(expecteds)))&#xA;AssertionError: Error code E_NETWORK_ERROR not matches expected: &#39;S_OK&#39;&#xA;&#xA;&#xA;Check that number of records for &#34;Calendars&#34; in manifest is equal to number of records in database&#xA;Step Execution Failure: &#39;0 is not equal to 220&#39;&#xA;Traceback (most recent call last):&#xA;  File &#34;C:\Users\mokych.andrey\AppData\Roaming\Python\Python37\site-packages\getgauge\executor.py&#34;, line 31, in execute_method&#xA;    func(*params)&#xA;  File &#34;F:\Work\oxygen\autotests\OxyMi\step_impl\verification_steps.py&#34;, line 82, in compare_records_from_manifest_and_database&#xA;    expect_eq(expected_count, actual_count)&#xA;  File &#34;F:\Work\oxygen\autotests\TestUtils\expects.py&#34;, line 8, in expect_eq&#xA;    raise AssertionError(error_message_format.format(actual=actual, expected=expected, **kwargs))&#xA;AssertionError: 0 is not equal to 220&#xA;</failure>
		</testcase>
		<testcase classname="OxyMi Calendars downloading" name="Get Calendars with USA proxy" time="23.841"></testcase>
		<system-out></system-out>
		<system-err></system-err>
	</testsuite>
</testsuites>
